<?xml version='1.0'?>
<sdf version='1.5'>
  <world name="default">

    <!-- A global light source -->
    <include>
      <uri>model://sun</uri>
    </include>

    <!-- A ground plane -->
    <include>
      <uri>model://ground_plane</uri>
    </include>

    <model name="velodyne_hdl-32">
      <!-- Give the base link a unique name -->
      <link name="base">
        <!-- Offset the base by half the lenght of the cylinder -->
        <pose>0 0 0.029335 0 0 0</pose>
        <inertial>
          <mass>1.2</mass>
          <inertia>
            <ixx>0.00089044</ixx>
            <ixy>0</ixy>
            <ixz>0</ixz>
            <iyy>0.00089044</iyy>
            <iyz>0</iyz>
            <izz>0.00109244</izz>
          </inertia>
        </inertial>
        <collision name="base_collision">
          <geometry>
            <cylinder>
              <!-- Radius and length provided by Velodyne -->
              <radius>0.04267</radius>
              <length>0.05867</length>
            </cylinder>
          </geometry>
        </collision>

        <!-- The visual is mostly a copy of the collision -->
        <visual name="base_visual">
          <geometry>
            <cylinder>
              <radius>0.04267</radius>
              <length>0.05867</length>
            </cylinder>
          </geometry>
        </visual>
      </link>

      <!-- Give the top link a unique name -->
      <link name="top">
        <!-- Vertically offset the top cylinder by
             the length of the bottom cylinder
             and half the length of this cylinder
             and clearance 2.2mm -->
        <pose>0 0 0.097655 0 0 0</pose>
        <inertial>
          <mass>0.1</mass>
          <inertia>
            <ixx>0.00009062</ixx>
            <ixy>0</ixy>
            <ixz>0</ixz>
            <iyy>0.00009062</iyy>
            <iyz>0</iyz>
            <izz>0.00009104</izz>
          </inertia>
        </inertial>
        <collision name="top_collision">
          <geometry>
            <cylinder>
              <!-- Radius and length provided by Velodyne -->
              <radius>0.04267</radius>
              <length>0.07357</length>
            </cylinder>
          </geometry>
        </collision>

        <!-- The visual is mostly a copy of the collision -->
        <visual name="top_visual">
          <geometry>
            <cylinder>
              <radius>0.04267</radius>
              <length>0.07357</length>
            </cylinder>
          </geometry>
        </visual>
      </link>
      <!-- Each joint must have a unique name -->
      <joint name="base_joint_top" type="revolute">
        <!-- Position the joint at the bottom of the top link -->
        <pose>0 0 -0.036785 0 0 0</pose>
        <parent>base</parent>
        <child>top</child>

        <!-- The axis defines the joint's degree of freedom -->
        <axis>
          <!-- Revolve around the z-axis -->
          <xyz>0 0 1</xyz>
          <!-- Limit refers to the range of motion of the joint -->
          <limit>
            <!-- Use a very large number to indicate a continuous revolution -->
            <lower>-10000000000000000</lower>
            <upper>10000000000000000</upper>
          </limit>
        </axis>
      </joint>
    </model>
  </world>
</sdf>
