<?xml version='1.0'?>
<sdf version='1.5'>
  <world name="default">

    <!-- A global light source -->
    <include>
      <uri>model://sun</uri>
    </include>

    <!-- A ground plane -->
    <include>
      <uri>model://ground_plane</uri>
    </include>

    <model name="velodyne_hdl-32">
      <!-- Give the base link a unique name -->
      <link name="base">
        <!-- Offset the base by half the lenght of the cylinder -->
        <pose>0 0 0.029335 0 0 0</pose>
        <inertial>
          <mass>1.2</mass>
          <inertia>
            <ixx>0.00089044</ixx>
            <ixy>0</ixy>
            <ixz>0</ixz>
            <iyy>0.00089044</iyy>
            <iyz>0</iyz>
            <izz>0.00109244</izz>
          </inertia>
        </inertial>
        <collision name="base_collision">
          <geometry>
            <cylinder>
              <!-- Radius and length provided by Velodyne -->
              <radius>0.04267</radius>
              <length>0.05867</length>
            </cylinder>
          </geometry>
        </collision>

        <!-- The visual is mostly a copy of the collision -->
        <visual name="base_visual">
          <geometry>
            <cylinder>
              <radius>0.04267</radius>
              <length>0.05867</length>
            </cylinder>
          </geometry>
        </visual>
      </link>

      <!-- Give the top link a unique name -->
      <link name="top">
        <!-- Vertically offset the top cylinder by
             the length of the bottom cylinder
             and half the length of this cylinder
             and clearance 2.2mm -->
        <pose>0 0 0.097655 0 0 0</pose>
        <inertial>
          <mass>0.1</mass>
          <inertia>
            <ixx>0.00009062</ixx>
            <ixy>0</ixy>
            <ixz>0</ixz>
            <iyy>0.00009062</iyy>
            <iyz>0</iyz>
            <izz>0.00009104</izz>
          </inertia>
        </inertial>
        <collision name="top_collision">
          <geometry>
            <cylinder>
              <!-- Radius and length provided by Velodyne -->
              <radius>0.04267</radius>
              <length>0.07357</length>
            </cylinder>
          </geometry>
        </collision>

        <!-- The visual is mostly a copy of the collision -->
        <visual name="top_visual">
          <geometry>
            <cylinder>
              <radius>0.04267</radius>
              <length>0.07357</length>
            </cylinder>
          </geometry>
        </visual>
        <!-- Add a ray sensor, and give it a name -->
        <sensor type="ray" name="sensor">
          <!-- Position the ray sensor based on the specification.
               Also rotate it by 90 degrees around the X-axis
               so that the <horizontal> ray become vertical -->
          <pose>0 0 -0.004645 1.5707 0 0</pose>
          <!-- Enable visualization to see the rays in the GUI -->
          <visualize>true</visualize>
          <!-- Set the update rate of the sensor -->
          <update_rate>30</update_rate>
          <ray>
            <!-- The scan element contains the horizontal and vertical beams.
               We are leaving out the vertical beams for this tutorial. -->
            <scan>
              <!-- The horizontal beams -->
              <horizontal>
                <!-- The velodyne has 32 beams(samples) -->
                <samples>32</samples>
                <!-- Resolution is multiplied by samples to determine
                     number of simulated beams vs interpolated beams. See:
                     http://sdformat.org/spec?ver=1.6&elem=sensor#horizontal_resolution
                -->
                <resolution>1</resolution>
                <!-- Minimum angle in radians -->
                <min_angle>-0.53529248</min_angle>
                <!-- Maximum angle in radians -->
                <max_angle>0.18622663</max_angle>
              </horizontal>
            </scan>
            <!-- Range defines characteristics of an individual beam -->
            <range>
              <!-- Minimum distance of the beam -->
              <min>0.05</min>
              <!-- Maximum distance of the beam -->
              <max>70</max>
              <!-- Linear resolution of the beam -->
              <resolution>0.02</resolution>
            </range>
          </ray>
        </sensor>
      </link>
      <!-- Each joint must have a unique name -->
      <joint name="base_joint_top" type="revolute">
        <!-- Position the joint at the bottom of the top link -->
        <pose>0 0 -0.036785 0 0 0</pose>
        <parent>base</parent>
        <child>top</child>

        <!-- The axis defines the joint's degree of freedom -->
        <axis>
          <!-- Revolve around the z-axis -->
          <xyz>0 0 1</xyz>
          <!-- Limit refers to the range of motion of the joint -->
          <limit>
            <!-- Use a very large number to indicate a continuous revolution -->
            <lower>-10000000000000000</lower>
            <upper>10000000000000000</upper>
          </limit>
        </axis>
      </joint>
    </model>
  </world>
</sdf>
